<?xml version="1.0" ?>
<!-- =================================================================================== -->
<!-- |    This document was autogenerated by xacro from 2wd_robot.xacro                | -->
<!-- |    EDITING THIS FILE BY HAND IS NOT RECOMMENDED                                 | -->
<!-- =================================================================================== -->
<!-- THIS IS NECESSARY -->
<robot name="2wd_robot" xmlns:xacro="http://www.ros.org/wiki/xacro">
  <material name="black">
    <color rgba="0.0 0.0 0.0 1.0"/>
  </material>
  <material name="blue">
    <color rgba="0.0 0.0 0.8 1.0"/>
  </material>
  <material name="green">
    <color rgba="0.0 0.8 0.0 1.0"/>
  </material>
  <material name="grey">
    <color rgba="0.2 0.2 0.2 1.0"/>
  </material>
  <material name="orange">
    <color rgba="1.0 0.423529411765 0.0392156862745 1.0"/>
  </material>
  <material name="brown">
    <color rgba="0.870588235294 0.811764705882 0.764705882353 1.0"/>
  </material>
  <material name="red">
    <color rgba="0.8 0.0 0.0 1.0"/>
  </material>
  <material name="white">
    <color rgba="1.0 1.0 1.0 1.0"/>
  </material>
  <gazebo reference="base_link">
    <material>Gazebo/Blue</material>
    <pose>0 0 0 0 0 0</pose>
  </gazebo>
  <gazebo reference="right_wheel">
    <material>Gazebo/Grey</material>
  </gazebo>
  <gazebo reference="left_wheel">
    <material>Gazebo/Grey</material>
  </gazebo>
  <!-- Include Gazebo Tags -->
  <!--////////////////////////////////// LINKS //////////////////////////////// -->
  <!-- in radians -->
  <!-- Actual body/chassis of the robot -->
  <link name="base_link">
    <!-- 1) Add Interia for Base -->
    <inertial>
      <mass value="5"/>
      <origin xyz="0 0 0"/>
      <inertia ixx="0.254166666667" ixy="0" ixz="0" iyx="0" iyy="0.166666666667" iyz="0" izx="0" izy="0" izz="0.120833333333"/>
    </inertial>
    <!-- 2) Add Visual for Base -->
    <visual>
      <origin rpy="1.5708 0 0" xyz="0 0 0"/>
      <geometry>
        <!--length(depth) x width x height -->
        <box size="0.6 0.2 0.5"/>
      </geometry>
      <material name="blue"/>
    </visual>
    <!-- 3) Add Collision for Base -->
    <collision>
      <origin rpy="1.5708 0 0 " xyz="0 0 0"/>
      <geometry>
        <!--length(depth) x width x height -->
        <box size="0.6 0.2 0.5 "/>
      </geometry>
    </collision>
    <!-- 4) Caster Visual (optional) -->
    <visual name="caster">
      <origin rpy="0 0 0" xyz="-0.2 0 -0.125"/>
      <geometry>
        <sphere radius="0.04"/>
      </geometry>
    </visual>
    <!-- 5) Caster Collision (optional) -->
    <collision>
      <origin rpy="0 0 0" xyz="-0.2 0 -0.125"/>
      <geometry>
        <sphere radius="0.04"/>
      </geometry>
    </collision>
  </link>
  <!-- in kg-->
  <!-- in m-->
  <!-- Right Wheel -->
  <link name="right_wheel">
    <!-- 1) Add Interia for Front Right Wheel -->
    <inertial>
      <mass value="2.5"/>
      <origin xyz="0 0 0"/>
      <inertia ixx="0.0270833333333" ixy="0" ixz="0" iyx="0" iyy="0.0270833333333" iyz="0" izx="0" izy="0" izz="0.05"/>
    </inertial>
    <!-- 2) Add Visual for Right Wheel -->
    <visual>
      <origin rpy="0 0 0" xyz="0 0 0"/>
      <!-- 90 because we want the wheel up not flat down -->
      <geometry>
        <mesh filename="package://2wd_robot_description/meshes/wheel.stl" scale="1 1 1"/>
      </geometry>
      <material name="grey"/>
    </visual>
    <!-- 3) Add Collision for Front Right Wheel -->
    <collision>
      <origin rpy="0 0 0 " xyz="0 0 0"/>
      <geometry>
        <mesh filename="package://2wd_robot_description/meshes/wheel.stl" scale="1 1 1"/>
      </geometry>
    </collision>
  </link>
  <!-- Left Wheel -->
  <link name="left_wheel">
    <!-- 1) Add Interia for Front Left Wheel -->
    <inertial>
      <mass value="2.5"/>
      <origin xyz="0 0 0"/>
      <inertia ixx="0.0270833333333" ixy="0" ixz="0" iyx="0" iyy="0.0270833333333" iyz="0" izx="0" izy="0" izz="0.05"/>
    </inertial>
    <!-- 2) Add Visual for Front Left Wheel -->
    <visual>
      <origin rpy="0 0 0" xyz="0 0 0"/>
      <!-- 90 because we want the wheel up not flat down -->
      <geometry>
        <mesh filename="package://2wd_robot_description/meshes/wheel.stl" scale="1 1 1"/>
      </geometry>
      <material name="grey"/>
    </visual>
    <!-- 3) Add Collision for Front Left Wheel -->
    <collision>
      <origin rpy="0 0 0 " xyz="0 0 0"/>
      <geometry>
        <mesh filename="package://2wd_robot_description/meshes/wheel.stl" scale="1 1 1"/>
      </geometry>
    </collision>
  </link>
  <!-- yaw:   in m -->
  <!-- Right Wheel <-> Base -->
  <joint name="joint_f_r_wheel" type="continuous">
    <parent link="base_link"/>
    <child link="right_wheel"/>
    <origin rpy="0.0 0.0 0.0" xyz="0.25 -0.31 0.0"/>
    <!-- Axis of revoltuion. Right hand rule says Y will be rotating  -->
    <axis rpy="0 0 0" xyz="0 1 0"/>
  </joint>
  <!-- Left wheel <-> Base -->
  <joint name="joint_f_l_wheel" type="continuous">
    <parent link="base_link"/>
    <child link="left_wheel"/>
    <origin rpy="0.0 0.0 0.0" xyz="0.25 0.31 0.0"/>
    <!-- Axis of revoltuion. Right hand rule says Y will be rotating  -->
    <axis rpy="0 0 0" xyz="0 1 0"/>
  </joint>
  <!--///////////////////////////// END OF ROBOT ///////////////////////////////////////// -->
</robot>

